---
sidebar_label: URDF Overview
title: URDF Overview - Unified Robot Description Format for Robot Modeling
description: Understanding URDF and its applications in robot modeling and simulation
keywords: [URDF, robot description, modeling, simulation, robotics, XML, robot models]
---

# 3.4 URDF Overview

## Introduction

URDF (Unified Robot Description Format) is an XML-based format used to describe robot models in ROS. It defines the physical and visual properties of robots, including their structure, joints, links, and associated properties. URDF is fundamental to robot simulation, visualization, and control in ROS-based systems.

URDF enables the representation of complex robots with multiple degrees of freedom, sensors, and actuators in a standardized format. This allows for the creation of detailed robot models that can be used across different ROS tools, simulation environments, and real-world robotic applications.

## URDF Fundamentals

### Core Concepts

#### Links
Links represent the rigid bodies of a robot. Each link has:
- **Physical properties**: Mass, center of mass, inertia
- **Visual properties**: Shape, color, mesh for visualization
- **Collision properties**: Shape for collision detection
- **Name**: Unique identifier within the robot model

#### Joints
Joints define the connection between links and specify how they can move relative to each other:
- **Joint type**: Fixed, continuous, revolute, prismatic, floating, planar
- **Limits**: Range of motion and velocity/effort constraints
- **Origin**: Position and orientation relative to parent link
- **Axis**: Direction of motion for movable joints

#### Transmissions
Transmissions define the relationship between actuators and joints:
- **Simple transmissions**: Direct relationship between actuator and joint
- **Differential transmissions**: Multiple actuators controlling one joint
- **Four-bar linkage**: Complex mechanical relationships

### URDF Syntax

#### Basic Structure
```xml
<?xml version="1.0"?>
<robot name="my_robot" xmlns:xacro="http://www.ros.org/wiki/xacro">
  <!-- Links -->
  <link name="base_link">
    <inertial>
      <mass value="1.0"/>
      <origin xyz="0 0 0" rpy="0 0 0"/>
      <inertia ixx="0.1" ixy="0.0" ixz="0.0" iyy="0.1" iyz="0.0" izz="0.1"/>
    </inertial>
    
    <visual>
      <origin xyz="0 0 0" rpy="0 0 0"/>
      <geometry>
        <cylinder length="0.2" radius="0.1"/>
      </geometry>
      <material name="blue">
        <color rgba="0 0 1 1"/>
      </material>
    </visual>
    
    <collision>
      <origin xyz="0 0 0" rpy="0 0 0"/>
      <geometry>
        <cylinder length="0.2" radius="0.1"/>
      </geometry>
    </collision>
  </link>
  
  <!-- Joints -->
  <joint name="fixed_joint" type="fixed">
    <parent link="base_link"/>
    <child link="sensor_link"/>
    <origin xyz="0 0 0.2" rpy="0 0 0"/>
  </joint>
  
  <link name="sensor_link">
    <!-- Link definition -->
  </link>
</robot>
```

### Link Properties

#### Inertial Properties
```xml
<inertial>
  <mass value="1.0"/>                    <!-- Mass in kg -->
  <origin xyz="0 0 0" rpy="0 0 0"/>    <!-- Center of mass -->
  <inertia ixx="0.1" ixy="0.0" ixz="0.0" 
           iyy="0.1" iyz="0.0" izz="0.1"/> <!-- Inertia matrix -->
</inertial>
```

#### Visual Properties
```xml
<visual>
  <origin xyz="0 0 0" rpy="0 0 0"/>    <!-- Offset from link origin -->
  <geometry>
    <box size="0.1 0.1 0.1"/>         <!-- Box shape -->
    <!-- OR -->
    <cylinder radius="0.1" length="0.2"/> <!-- Cylinder shape -->
    <!-- OR -->
    <sphere radius="0.1"/>             <!-- Sphere shape -->
    <!-- OR -->
    <mesh filename="package://my_robot/meshes/link.stl"/> <!-- Mesh file -->
  </geometry>
  <material name="red">
    <color rgba="1 0 0 1"/>            <!-- Color with alpha -->
  </material>
</visual>
```

#### Collision Properties
```xml
<collision>
  <origin xyz="0 0 0" rpy="0 0 0"/>
  <geometry>
    <cylinder radius="0.1" length="0.2"/> <!-- Collision geometry -->
  </geometry>
</collision>
```

### Joint Properties

#### Joint Types
- **fixed**: No movement allowed
- **continuous**: Continuous rotation (like a wheel)
- **revolute**: Limited rotation with defined limits
- **prismatic**: Linear sliding motion with limits
- **floating**: 6-DOF movement (no constraints)
- **planar**: Planar motion (3-DOF)

#### Joint Definition
```xml
<joint name="joint_name" type="revolute">
  <parent link="parent_link"/>
  <child link="child_link"/>
  <origin xyz="0 0 0.1" rpy="0 0 0"/>    <!-- Position relative to parent -->
  <axis xyz="0 0 1"/>                     <!-- Axis of rotation -->
  <limit lower="-1.57" upper="1.57"       <!-- Joint limits -->
         effort="100" velocity="1"/>
  <dynamics damping="0.1" friction="0.0"/> <!-- Joint dynamics -->
</joint>
```

## Advanced URDF Features

### Materials

#### Defining Materials
```xml
<material name="light_grey">
  <color rgba="0.7 0.7 0.7 1.0"/>
</material>

<material name="dark_grey">
  <color rgba="0.4 0.4 0.4 1.0"/>
</material>

<material name="orange">
  <color rgba="1.0 0.423529411765 0.0392156862745 1.0"/>
</material>
```

### Gazebo Extensions

#### Adding Gazebo-Specific Properties
```xml
<gazebo reference="link_name">
  <material>Gazebo/Orange</material>
  <mu1>0.2</mu1>
  <mu2>0.2</mu2>
  <kp>1000000.0</kp>
  <kd>100.0</kd>
</gazebo>

<gazebo>
  <plugin name="diff_drive" filename="libgazebo_ros_diff_drive.so">
    <left_joint>left_wheel_joint</left_joint>
    <right_joint>right_wheel_joint</right_joint>
    <wheel_separation>0.3</wheel_separation>
    <wheel_diameter>0.15</wheel_diameter>
  </plugin>
</gazebo>
```

### Sensors

#### Adding Sensors to URDF
```xml
<link name="camera_link">
  <visual>
    <geometry>
      <box size="0.02 0.08 0.03"/>
    </geometry>
  </visual>
</link>

<joint name="camera_joint" type="fixed">
  <parent link="base_link"/>
  <child link="camera_link"/>
  <origin xyz="0.1 0 0.05" rpy="0 0 0"/>
</joint>

<gazebo reference="camera_link">
  <sensor type="camera" name="camera1">
    <pose>0 0 0 0 0 0</pose>
    <visualize>true</visualize>
    <update_rate>30.0</update_rate>
    <camera name="head">
      <horizontal_fov>1.3962634</horizontal_fov>
      <image>
        <width>800</width>
        <height>800</height>
        <format>R8G8B8</format>
      </image>
      <clip>
        <near>0.02</near>
        <far>300</far>
      </clip>
    </camera>
    <plugin name="camera_controller" filename="libgazebo_ros_camera.so">
      <frame_name>camera_link</frame_name>
    </plugin>
  </sensor>
</gazebo>
```

## URDF Tools and Ecosystem

### xacro (XML Macros)

xacro allows parameterization and macro expansion in URDF files:

#### Basic xacro Example
```xml
<?xml version="1.0"?>
<robot xmlns:xacro="http://www.ros.org/wiki/xacro" name="my_robot">

  <!-- Properties -->
  <xacro:property name="M_PI" value="3.1415926535897931" />
  <xacro:property name="base_width" value="0.5" />
  <xacro:property name="base_length" value="0.6" />
  <xacro:property name="base_height" value="0.2" />

  <!-- Macro -->
  <xacro:macro name="cylinder_inertia" params="m r h">
    <inertia  ixx="${m*(3*r*r+h*h)/12}" ixy = "0" ixz = "0"
              iyy="${m*(3*r*r+h*h)/12}" iyz = "0"
              izz="${m*r*r/2}" />
  </xacro:macro>

  <!-- Link using macro -->
  <link name="base_link">
    <inertial>
      <mass value="10.0"/>
      <origin xyz="0 0 0" rpy="0 0 0"/>
      <xacro:cylinder_inertia m="10.0" r="${base_width/2}" h="${base_height}"/>
    </inertial>
    
    <visual>
      <origin xyz="0 0 0" rpy="0 0 0"/>
      <geometry>
        <cylinder radius="${base_width/2}" length="${base_height}"/>
      </geometry>
    </visual>
    
    <collision>
      <origin xyz="0 0 0" rpy="0 0 0"/>
      <geometry>
        <cylinder radius="${base_width/2}" length="${base_height}"/>
      </geometry>
    </collision>
  </link>
</robot>
```

### URDF Tools

#### Command Line Tools
```bash
# Check URDF validity
check_urdf my_robot.urdf

# Parse xacro to URDF
xacro my_robot.xacro > my_robot.urdf

# Display URDF in tree format
urdf_to_graphviz my_robot.urdf
```

#### RViz Visualization
- Real-time robot model visualization
- Joint state display
- TF frame visualization
- Sensor data overlay

### Robot State Publisher

The robot_state_publisher node:
- Reads joint states from the `/joint_states` topic
- Calculates forward kinematics
- Publishes TF transforms for the robot
- Enables visualization and navigation

## Robot Model Applications

### Simulation

#### Gazebo Integration
- Physics simulation with realistic dynamics
- Sensor simulation for cameras, IMUs, LiDAR
- Collision detection and response
- Environment interaction

#### Unity Robotics Integration
- Physics simulation in Unity environment
- Sensor simulation using Unity's rendering pipeline
- Heterogeneous simulation environments
- VR/AR applications

### Visualization

#### RViz Display
- 3D robot model visualization
- Joint state display
- Sensor data overlay
- Path planning visualization

#### Web Visualization
- Three.js-based web visualization
- Real-time robot state display
- Remote monitoring interfaces
- Interactive control panels

### Control and Planning

#### Kinematics Solvers
- Forward kinematics calculation
- Inverse kinematics solvers
- Trajectory planning
- Collision checking

#### MoveIt! Integration
- Motion planning with collision avoidance
- Inverse kinematics solvers
- Trajectory execution
- Grasp planning

## Best Practices

### Model Organization

#### Hierarchical Structure
- Organize links in a logical tree structure
- Use meaningful names for links and joints
- Group related components logically
- Follow consistent naming conventions

#### Modular Design
- Create reusable components
- Parameterize models with xacro
- Separate visual and collision geometries appropriately
- Use standard coordinate frames

### Performance Considerations

#### Mesh Optimization
- Use simplified meshes for collision detection
- Optimize mesh resolution for visualization
- Consider Level of Detail (LOD) approaches
- Balance accuracy with performance

#### Inertial Properties
- Accurate inertial properties for simulation
- Estimate or measure real robot properties
- Consider composite materials
- Account for payloads and attachments

### Accuracy and Validation

#### Real Robot Correlation
- Measure actual robot dimensions
- Verify joint limits and ranges
- Validate sensor placements
- Calibrate inertial parameters

#### Simulation Fidelity
- Match real robot dynamics in simulation
- Validate sensor models
- Test control algorithms in simulation first
- Gradually transfer to real robot

## Common URDF Patterns

### Wheeled Robots

#### Differential Drive
```xml
<joint name="left_wheel_joint" type="continuous">
  <parent link="base_link"/>
  <child link="left_wheel_link"/>
  <origin xyz="0 ${wheel_track/2} ${wheel_radius}" rpy="${-M_PI/2} 0 0"/>
  <axis xyz="0 0 1"/>
</joint>

<joint name="right_wheel_joint" type="continuous">
  <parent link="base_link"/>
  <child link="right_wheel_link"/>
  <origin xyz="0 ${-wheel_track/2} ${wheel_radius}" rpy="${-M_PI/2} 0 0"/>
  <axis xyz="0 0 1"/>
</joint>
```

### Manipulator Arms

#### Serial Chain Structure
```xml
<!-- Base to shoulder -->
<joint name="shoulder_pan_joint" type="revolute">
  <parent link="base_link"/>
  <child link="shoulder_link"/>
  <origin xyz="0 0 ${base_height}" rpy="0 0 0"/>
  <axis xyz="0 0 1"/>
  <limit lower="${-M_PI}" upper="${M_PI}" effort="100" velocity="1"/>
</joint>

<!-- Shoulder to elbow -->
<joint name="shoulder_lift_joint" type="revolute">
  <parent link="shoulder_link"/>
  <child link="upper_arm_link"/>
  <origin xyz="${shoulder_offset} 0 0" rpy="0 ${-M_PI/2} 0"/>
  <axis xyz="0 1 0"/>
  <limit lower="${-M_PI/2}" upper="${M_PI/2}" effort="100" velocity="1"/>
</joint>
```

### Humanoid Robots

#### Biped Structure
```xml
<!-- Main body structure -->
<joint name="torso_joint" type="fixed">
  <parent link="base_link"/>
  <child link="torso_link"/>
</joint>

<!-- Leg structure -->
<joint name="left_hip_joint" type="revolute">
  <parent link="torso_link"/>
  <child link="left_thigh_link"/>
  <origin xyz="0 ${hip_offset} ${torso_length/2}" rpy="0 0 0"/>
  <axis xyz="0 0 1"/>
  <limit lower="${-M_PI/4}" upper="${M_PI/4}" effort="100" velocity="1"/>
</joint>
```

## Integration with Physical AI Systems

### Hardware-in-the-Loop Simulation

#### Real Sensor Integration
- Combine real sensor data with simulated robot
- Validate control algorithms in mixed environments
- Bridge simulation and reality
- Reduce development risks

#### Actuator Modeling
- Model real actuator characteristics
- Include backlash and friction models
- Account for control delays
- Validate control strategies

### Perception Integration

#### Sensor Modeling
- Accurate sensor placement in URDF
- Field of view and range specifications
- Noise and accuracy modeling
- Multi-sensor fusion preparation

#### Environment Interaction
- Collision detection with environment
- Contact force calculation
- Ground truth for evaluation
- Simulation-to-reality transfer

### Control System Design

#### Forward Kinematics
- Calculate end-effector positions
- Validate joint limits
- Implement singularity detection
- Prepare for inverse kinematics

#### Inverse Kinematics
- Solve for joint angles from end-effector poses
- Implement redundancy resolution
- Handle joint limits and constraints
- Optimize for multiple objectives

## Troubleshooting Common Issues

### URDF Parsing Errors

#### Common Issues
- **Malformed XML**: Check for proper closing tags
- **Missing dependencies**: Ensure all referenced files exist
- **Invalid values**: Check for NaN or infinite values
- **Joint limit conflicts**: Verify joint limits are valid

#### Validation Tools
```bash
# Validate URDF
check_urdf my_robot.urdf

# Check specific aspects
roslaunch urdf_tutorial check.launch model:=my_robot.urdf
```

### Simulation Issues

#### Physics Problems
- **Unstable simulation**: Check mass and inertia values
- **Penetration**: Verify collision geometries
- **Incorrect motion**: Check joint types and limits
- **Performance**: Optimize mesh complexity

#### Visualization Problems
- **Missing models**: Check mesh file paths
- **Wrong colors**: Verify material definitions
- **Incorrect poses**: Check origins and orientations
- **Missing parts**: Verify all links are connected

## Advanced Topics

### URDF++ (SDF)

For more complex scenarios, SDF (Simulation Description Format) offers additional capabilities:
- Multi-body systems
- Complex joint types
- Advanced physics properties
- Environment description

### Dynamic URDF

#### Runtime Model Changes
- Reconfigure robot structure at runtime
- Add/remove links and joints
- Adapt to changing payloads
- Modify for different tasks

### Multi-Robot Systems

#### Fleet Management
- Coordinate multiple robot models
- Manage namespaces and TF frames
- Handle inter-robot collisions
- Coordinate shared environments

## Security Considerations

### Model Integrity
- Validate URDF files before loading
- Check for malicious content in mesh files
- Verify model authenticity
- Implement model signing if needed

### Simulation Security
- Isolate simulation environments
- Validate sensor data feeds
- Monitor for unexpected behavior
- Implement sandboxing where possible

## Performance Optimization

### Real-time Considerations
- Optimize collision meshes for performance
- Reduce unnecessary detail in simulation
- Use simplified models for planning
- Consider Level of Detail (LOD) approaches

### Memory Management
- Efficient mesh loading
- Cache frequently accessed models
- Streamline TF tree updates
- Optimize kinematic calculations

## Future Developments

### Emerging Standards

#### USD (Universal Scene Description)
- NVIDIA's format for 3D scenes
- Growing support in robotics
- Advanced material and lighting models
- Integration with Isaac Sim

#### GLTF for Robotics
- Web-friendly 3D format
- Growing ecosystem
- Real-time rendering capabilities
- Cross-platform compatibility

### AI Integration

#### Learning-Based Models
- Neural networks for robot dynamics
- Learned kinematic models
- Adaptive simulation parameters
- Physics-informed ML models

## Conclusion

URDF is a fundamental component of the ROS ecosystem, enabling the standardized description of robot models for simulation, visualization, and control. Understanding URDF structure, properties, and best practices is essential for developing effective robotic systems.

The format's flexibility allows for the description of complex robots with multiple degrees of freedom, sensors, and actuators. When combined with tools like xacro, Gazebo, and MoveIt!, URDF enables the creation of sophisticated robotic applications from simulation to real-world deployment.

As robotics continues to advance toward more complex and capable systems, URDF and related formats will continue to evolve to meet new challenges while maintaining the standardization and interoperability that make ROS-based development possible.

## Exercises

1. Create a URDF model for a simple wheeled robot with sensors, including proper inertial, visual, and collision properties.
2. Design a manipulator arm URDF model with multiple joints and validate it using URDF tools.
3. Research and compare URDF with other robot description formats (SDF, MJCF, USD) for different robotics applications.

## Further Reading

- ROS Documentation: "URDF Tutorials"
- ROS Documentation: "Working with Robots in URDF"
- Robotics Library: "Robot Model Documentation"
- Gazebo Documentation: "URDF Integration"
- MoveIt! Documentation: "Robot Model Setup"